<?xml version="1.0" ?>
<!-- =================================================================================== -->
<!-- |    This document was autogenerated by xacro from rosbot/rosbot.urdf.xacro       | -->
<!-- |    EDITING THIS FILE BY HAND IS NOT RECOMMENDED                                 | -->
<!-- =================================================================================== -->
<robot name="rosbot">
  <material name="Black">
    <color rgba="0.0 0.0 0.0 1.0"/>
  </material>
  <material name="Blue">
    <color rgba="0.0 0.0 0.8 1.0"/>
  </material>
  <material name="Green">
    <color rgba="0.0 0.8 0.0 1.0"/>
  </material>
  <material name="Grey">
    <color rgba="0.5 0.5 0.5 1.0"/>
  </material>
  <material name="DarkGrey">
    <color rgba="0.2 0.2 0.2 1.0"/>
  </material>
  <material name="Orange">
    <color rgba="1.0 0.4235294117647059 0.0392156862745098 1.0"/>
  </material>
  <material name="Brown">
    <color rgba="0.8705882352941177 0.8117647058823529 0.7647058823529411 1.0"/>
  </material>
  <material name="Red">
    <color rgba="0.8 0.0 0.0 1.0"/>
  </material>
  <material name="White">
    <color rgba="1.0 1.0 1.0 1.0"/>
  </material>
  <link name="base_link"/>
  <link name="body_link">
    <visual>
      <geometry>
        <mesh filename="file:/robot_model/meshes/body.stl" scale="0.001 0.001 0.001"/>
      </geometry>
      <origin rpy="1.5707963267948966 0.0 1.5707963267948966" xyz="0.0 0.0 -0.02"/>
      <material name="White"/>
    </visual>
    <collision>
      <geometry>
        <box size="0.197 0.150 0.080"/>
      </geometry>
      <origin rpy="0.0 0.0 0.0" xyz="0.0 0.0 0.02"/>
    </collision>
    <inertial>
      <mass value="2.0"/>
      <inertia ixx="0.001" ixy="0.000" ixz="0.000" iyy="0.001" iyz="0.000" izz="0.001"/>
    </inertial>
  </link>
  <link name="cover_link">
    <visual>
      <geometry>
        <mesh filename="file:/robot_model/meshes/cover.stl" scale="0.001 0.001 0.001"/>
      </geometry>
      <origin rpy="1.5707963267948966 0.0 1.5707963267948966" xyz="0.0 0.0 -0.002"/>
      <material name="Red"/>
    </visual>
    <inertial>
      <mass value="0.000001"/>
      <inertia ixx="1.0" ixy="0.0" ixz="0.0" iyy="1.0" iyz="0.0" izz="0.0"/>
    </inertial>
  </link>
  <link name="imu_link">
    <inertial>
      <mass value="0.001"/>
      <inertia ixx="1" ixy="0" ixz="0" iyy="1" iyz="0" izz="1"/>
    </inertial>
  </link>
  <link name="camera_link">
    <inertial>
      <mass value="0.000001"/>
      <inertia ixx="1" ixy="0" ixz="0" iyy="1" iyz="0" izz="1"/>
    </inertial>
  </link>
  <joint name="base_link_to_body_joint" type="fixed">
    <origin rpy="0.0 0.0 0.0" xyz="0.0 0.0 0.0425"/>
    <parent link="base_link"/>
    <child link="body_link"/>
  </joint>
  <joint name="body_to_cover_joint" type="fixed">
    <origin rpy="0.0 0.0 0.0" xyz="0.0 0.0 0.060"/>
    <parent link="body_link"/>
    <child link="cover_link"/>
  </joint>
  <joint name="body_link_to_imu_link_joint" type="fixed">
    <origin rpy="0.0 0.0 0.0" xyz="-0.1369 -0.0419 0.0370"/>
    <parent link="body_link"/>
    <child link="imu_link"/>
  </joint>
  <joint name="body_link_to_camera_link_joint" type="fixed">
    <origin rpy="0.0 0.0 0.0" xyz="-0.0141 0.0 0.125"/>
    <parent link="body_link"/>
    <child link="camera_link"/>
  </joint>
  <gazebo reference="body_link">
    <material>Gazebo/White</material>
  </gazebo>
  <gazebo reference="cover_link">
    <material>Gazebo/Red</material>
  </gazebo>
  <joint name="range_left_front_joint" type="fixed">
    <axis xyz="0 1 0"/>
    <origin rpy="0 0 0.13 " xyz="0.1 0.05 0.01"/>
    <parent link="body_link"/>
    <child link="range_left_front"/>
  </joint>
  <link name="range_left_front"/>
  <joint name="range_right_front_joint" type="fixed">
    <axis xyz="0 1 0"/>
    <origin rpy="0 0 -0.13 " xyz="0.1 -0.05 0.01"/>
    <parent link="body_link"/>
    <child link="range_right_front"/>
  </joint>
  <link name="range_right_front"/>
  <joint name="range_left_rear_joint" type="fixed">
    <axis xyz="0 1 0"/>
    <origin rpy="0 0 3.01 " xyz="-0.1 0.05 0.01"/>
    <parent link="body_link"/>
    <child link="range_left_rear"/>
  </joint>
  <link name="range_left_rear"/>
  <joint name="range_right_rear_joint" type="fixed">
    <axis xyz="0 1 0"/>
    <origin rpy="0 0 3.27 " xyz="-0.1 -0.05 0.01"/>
    <parent link="body_link"/>
    <child link="range_right_rear"/>
  </joint>
  <link name="range_right_rear"/>
  <link name="front_left_wheel_link">
    <visual>
      <geometry>
        <mesh filename="file:/robot_model/meshes/wheel.stl" scale="0.001 0.001 0.001"/>
      </geometry>
      <origin rpy="0.0 0.0 1.5707963267948966" xyz="0.0 0.012999999999999998 0.0"/>
      <material name="Black"/>
    </visual>
    <collision>
      <geometry>
        <cylinder length="0.036" radius="0.0425"/>
      </geometry>
      <origin rpy="1.5707963267948966 0.0 0.0" xyz="0.0 0.0 0.0"/>
    </collision>
    <inertial>
      <mass value="0.100"/>
      <inertia ixx="0.001" ixy="0.000" ixz="0.000" iyy="0.001" iyz="0.000" izz="0.001"/>
    </inertial>
  </link>
  <joint name="front_left_wheel_joint" type="continuous">
    <parent link="body_link"/>
    <child link="front_left_wheel_link"/>
    <origin rpy="0.0 0.0 0.0" xyz="0.053 0.096 0.0"/>
    <axis xyz="0.0 1.0 0.0"/>
    <limit effort="1.5" velocity="5.0"/>
    <dynamics damping="0.001" friction="0.001"/>
  </joint>
  <gazebo reference="front_left_wheel_link">
    <material>Gazebo/DarkGrey</material>
  </gazebo>
  <link name="front_right_wheel_link">
    <visual>
      <geometry>
        <mesh filename="file:/robot_model/meshes/wheel.stl" scale="0.001 0.001 0.001"/>
      </geometry>
      <origin rpy="0.0 0.0 -1.5707963267948966" xyz="0.0 -0.012999999999999998 0.0"/>
      <material name="Black"/>
    </visual>
    <collision>
      <geometry>
        <cylinder length="0.036" radius="0.0425"/>
      </geometry>
      <origin rpy="1.5707963267948966 0.0 0.0" xyz="0.0 0.0 0.0"/>
    </collision>
    <inertial>
      <mass value="0.100"/>
      <inertia ixx="0.001" ixy="0.000" ixz="0.000" iyy="0.001" iyz="0.000" izz="0.001"/>
    </inertial>
  </link>
  <joint name="front_right_wheel_joint" type="continuous">
    <parent link="body_link"/>
    <child link="front_right_wheel_link"/>
    <origin rpy="0.0 0.0 0.0" xyz="0.053 -0.096 0.0"/>
    <axis xyz="0.0 1.0 0.0"/>
    <limit effort="1.5" velocity="5.0"/>
    <dynamics damping="0.001" friction="0.001"/>
  </joint>
  <gazebo reference="front_right_wheel_link">
    <material>Gazebo/DarkGrey</material>
  </gazebo>
  <link name="rear_left_wheel_link">
    <visual>
      <geometry>
        <mesh filename="file:/robot_model/meshes/wheel.stl" scale="0.001 0.001 0.001"/>
      </geometry>
      <origin rpy="0.0 0.0 1.5707963267948966" xyz="0.0 0.012999999999999998 0.0"/>
      <material name="Black"/>
    </visual>
    <collision>
      <geometry>
        <cylinder length="0.036" radius="0.0425"/>
      </geometry>
      <origin rpy="1.5707963267948966 0.0 0.0" xyz="0.0 0.0 0.0"/>
    </collision>
    <inertial>
      <mass value="0.100"/>
      <inertia ixx="0.001" ixy="0.000" ixz="0.000" iyy="0.001" iyz="0.000" izz="0.001"/>
    </inertial>
  </link>
  <joint name="rear_left_wheel_joint" type="continuous">
    <parent link="body_link"/>
    <child link="rear_left_wheel_link"/>
    <origin rpy="0.0 0.0 0.0" xyz="-0.053 0.096 0.0"/>
    <axis xyz="0.0 1.0 0.0"/>
    <limit effort="1.5" velocity="5.0"/>
    <dynamics damping="0.001" friction="0.001"/>
  </joint>
  <gazebo reference="rear_left_wheel_link">
    <material>Gazebo/DarkGrey</material>
  </gazebo>
  <link name="rear_right_wheel_link">
    <visual>
      <geometry>
        <mesh filename="file:/robot_model/meshes/wheel.stl" scale="0.001 0.001 0.001"/>
      </geometry>
      <origin rpy="0.0 0.0 -1.5707963267948966" xyz="0.0 -0.012999999999999998 0.0"/>
      <material name="Black"/>
    </visual>
    <collision>
      <geometry>
        <cylinder length="0.036" radius="0.0425"/>
      </geometry>
      <origin rpy="1.5707963267948966 0.0 0.0" xyz="0.0 0.0 0.0"/>
    </collision>
    <inertial>
      <mass value="0.100"/>
      <inertia ixx="0.001" ixy="0.000" ixz="0.000" iyy="0.001" iyz="0.000" izz="0.001"/>
    </inertial>
  </link>
  <joint name="rear_right_wheel_joint" type="continuous">
    <parent link="body_link"/>
    <child link="rear_right_wheel_link"/>
    <origin rpy="0.0 0.0 0.0" xyz="-0.053 -0.096 0.0"/>
    <axis xyz="0.0 1.0 0.0"/>
    <limit effort="1.5" velocity="5.0"/>
    <dynamics damping="0.001" friction="0.001"/>
  </joint>
  <gazebo reference="rear_right_wheel_link">
    <material>Gazebo/DarkGrey</material>
  </gazebo>
  <!-- Controll robot wheels -->
  <gazebo>
    <plugin filename="libgazebo_ros_diff_drive.so" name="skid_steer_drive">
      <ros>
        </ros>
      <update_rate>10</update_rate>
      <num_wheel_pairs>2</num_wheel_pairs>
      <left_joint>front_left_wheel_joint</left_joint>
      <right_joint>front_right_wheel_joint</right_joint>
      <left_joint>rear_left_wheel_joint</left_joint>
      <right_joint>rear_right_wheel_joint</right_joint>
      <wheel_separation>0.192</wheel_separation>
      <wheel_separation>0.192</wheel_separation>
      <wheel_diameter>0.085</wheel_diameter>
      <wheel_diameter>0.085</wheel_diameter>
      <max_wheel_torque>1.5</max_wheel_torque>
      <max_wheel_acceleration>1.0</max_wheel_acceleration>
      <publish_odom>true</publish_odom>
      <publish_odom_tf>true</publish_odom_tf>
      <publish_wheel_tf>true</publish_wheel_tf>
      <odometry_frame>odom</odometry_frame>
      <robot_base_frame>base_link</robot_base_frame>
    </plugin>
  </gazebo>
  <!-- publish joint states -->
  <gazebo>
    <plugin filename="libgazebo_ros_joint_state_publisher.so" name="joint_states">
      <joint_name>front_left_wheel_joint</joint_name>
      <joint_name>front_right_wheel_joint</joint_name>
      <joint_name>rear_left_wheel_joint</joint_name>
      <joint_name>rear_right_wheel_joint</joint_name>
    </plugin>
  </gazebo>
  <!-- publish IMU -->
  <gazebo reference="imu_link">
    <sensor name="imu" type="imu">
      <always_on>true</always_on>
      <update_rate>25</update_rate>
      <plugin filename="libgazebo_ros_imu_sensor.so" name="bno055_imu_plugin">
        <ros>
          <argument>~/out:=imu/data/raw</argument>
        </ros>
      </plugin>
    </sensor>
  </gazebo>
  <link name="lidar_link">
    <visual>
      <geometry>
        <mesh filename="file:/robot_model/meshes/rplidar.stl" scale="0.001 0.001 0.001"/>
      </geometry>
      <origin rpy="1.5707963267948966 0.0 1.5707963267948966" xyz="0.0 0.0 0.0"/>
      <material name="Black"/>
    </visual>
    <collision>
      <geometry>
        <cylinder length="0.0408" radius="0.03625"/>
      </geometry>
      <origin rpy="0 0 0" xyz="0 0 0.0204"/>
    </collision>
    <inertial>
      <mass value="0.190"/>
      <inertia ixx="0.001" ixy="0" ixz="0" iyy="0.001" iyz="0" izz="0.001"/>
    </inertial>
  </link>
  <link name="lidar_link_laser_link"/>
  <joint name="body_link_to_lidar_link_joint" type="fixed">
    <origin rpy="0.0 0.0 -3.141592653589793" xyz="0.02 0.0 0.0"/>
    <parent link="cover_link"/>
    <child link="lidar_link"/>
  </joint>
  <joint name="lidar_link_laser_link_joint" type="fixed">
    <origin rpy="0 0 0" xyz="0 0 0.0335"/>
    <parent link="lidar_link"/>
    <child link="lidar_link_laser_link"/>
  </joint>
  <gazebo reference="lidar_link">
    <material>Gazebo/DarkGrey</material>
  </gazebo>
  <gazebo reference="lidar_link_laser_link">
    <sensor name="rplidar_a2_sensor" type="ray">
      <pose>0 0 0 0 0 0</pose>
      <visualize>false</visualize>
      <ray>
        <scan>
          <horizontal>
            <samples>400</samples>
            <resolution>1</resolution>
            <min_angle>-3.141592653589793</min_angle>
            <max_angle>3.141592653589793</max_angle>
          </horizontal>
        </scan>
        <range>
          <min>0.2</min>
          <max>16.0</max>
          <resolution>0.08</resolution>
        </range>
        <noise>
          <type>gaussian</type>
          <mean>0.05</mean>
          <stddev>0.01</stddev>
        </noise>
      </ray>
      <update_rate>10</update_rate>
      <plugin filename="libgazebo_ros_ray_sensor.so" name="scan">
        <ros>
          <argument>~/out:=laser/scan</argument>
        </ros>
        <output_type>sensor_msgs/LaserScan</output_type>
        <frame_name>lidar_link_laser_link</frame_name>
      </plugin>
    </sensor>
  </gazebo>
  <link name="orbbec_astra_link">
    <visual>
      <geometry>
        <mesh filename="file:/robot_model/meshes/astra.stl" scale="0.001 0.001 0.001"/>
      </geometry>
      <origin rpy="1.5707963267948966 0 1.5707963267948966" xyz="-0.01 0 0.025"/>
      <material name="Black"/>
    </visual>
    <collision>
      <geometry>
        <box size="0.165 0.04 0.05"/>
      </geometry>
      <origin rpy="0 0 1.5707963267948966" xyz="-0.01 0 0.025"/>
    </collision>
    <inertial>
      <mass value="0.105"/>
      <inertia ixx="0.001" ixy="0" ixz="0" iyy="0.001" iyz="0" izz="0.001"/>
    </inertial>
  </link>
  <link name="orbbec_astra_depth_link"/>
  <link name="orbbec_astra_depth_refference_link"/>
  <joint name="body_link_to_orbbec_astra_link_joint" type="fixed">
    <origin rpy="0.0 0.0 0.0" xyz="0.0 0.0 0.0"/>
    <parent link="camera_link"/>
    <child link="orbbec_astra_link"/>
  </joint>
  <joint name="orbbec_astra_depth_link_joint" type="fixed">
    <origin rpy="0.0 1.5707963267948966 0.0" xyz="0.01 0 0.035"/>
    <parent link="orbbec_astra_link"/>
    <child link="orbbec_astra_depth_link"/>
  </joint>
  <joint name="orbbec_astra_depth_link_refference_joint" type="fixed">
    <origin rpy="1.5707963267948966 -1.5707963267948966 0.0" xyz="0.0 0.0 0.0"/>
    <parent link="orbbec_astra_depth_link"/>
    <child link="orbbec_astra_depth_refference_link"/>
  </joint>
  <gazebo reference="orbbec_astra_link">
    <material>Gazebo/DarkGrey</material>
  </gazebo>
  <gazebo reference="orbbec_astra_depth_refference_link">
    <sensor name="orbbec_astra_camera" type="depth">
      <always_on>1</always_on>
      <update_rate>10</update_rate>
      <camera name="camera">
        <distortion>
          <k1>0.07</k1>
          <k2>0.00</k2>
          <k3>0.00</k3>
          <p1>0.00</p1>
          <p2>0.00</p2>
          <center>0.0 0.0</center>
        </distortion>
      </camera>
      <plugin filename="libgazebo_ros_camera.so" name="rgbd_camera">
        <ros>
          <namespace>orbbec_astra_camera</namespace>
          <argument>--ros-args --remap custom_camera/image_raw:=rgb/image_raw</argument>
          <argument>--ros-args --remap custom_camera/image_depth:=depth/image_raw</argument>
          <argument>--ros-args --remap custom_camera/camera_info:=rgb/camera_info</argument>
          <argument>--ros-args --remap custom_camera/camera_info_depth:=depth/camera_info</argument>
          <argument>--ros-args --remap custom_camera/points:=depth/points</argument>
        </ros>
        <camera_name>camera</camera_name>
        <frame_name>orbbec_astra_depth_link</frame_name>
        <hack_baseline>0.07</hack_baseline>
        <min_depth>0.6</min_depth>
        <max_depth>8.0</max_depth>
      </plugin>
    </sensor>
  </gazebo>
  <ros2_control name="imu" type="sensor">
    <hardware>
      <plugin>rosbot_hardware_interfaces/RosbotImuSensor</plugin>
    </hardware>
    <sensor name="imu">
      <state_interface name="orientation.x"/>
      <state_interface name="orientation.y"/>
      <state_interface name="orientation.z"/>
      <state_interface name="orientation.w"/>
      <state_interface name="angular_velocity.x"/>
      <state_interface name="angular_velocity.y"/>
      <state_interface name="angular_velocity.z"/>
      <state_interface name="linear_acceleration.x"/>
      <state_interface name="linear_acceleration.y"/>
      <state_interface name="linear_acceleration.z"/>
    </sensor>
  </ros2_control>
  <ros2_control name="wheels" type="system">
    <hardware>
      <plugin>rosbot_hardware_interfaces/RosbotSystem</plugin>
    </hardware>
    <joint name="front_left_wheel_joint">
      <command_interface name="velocity"/>
      <state_interface name="position"/>
      <state_interface name="velocity"/>
    </joint>
    <joint name="front_right_wheel_joint">
      <command_interface name="velocity"/>
      <state_interface name="position"/>
      <state_interface name="velocity"/>
    </joint>
    <joint name="rear_left_wheel_joint">
      <command_interface name="velocity"/>
      <state_interface name="position"/>
      <state_interface name="velocity"/>
    </joint>
    <joint name="rear_right_wheel_joint">
      <command_interface name="velocity"/>
      <state_interface name="position"/>
      <state_interface name="velocity"/>
    </joint>
  </ros2_control>
</robot>